<?xml version="1.0" encoding="utf-8"?>
<!-- This URDF was automatically created by SolidWorks to URDF Exporter! Originally created by Stephen Brawner (brawner@gmail.com) 
     Commit Version: 1.6.0-4-g7f85cfe  Build Version: 1.6.7995.38578
     For more information, please see http://wiki.ros.org/sw_urdf_exporter -->
<robot
  name="mechatronic_wheel_urdf">
  <mujoco>
    <compiler
      meshdir="../meshes"
      discardvisual="false"
      strippath="true"
      fusestatic="false"/>
  </mujoco>
  <link
    name="Body">
    <inertial>
      <origin
        xyz="-0.076051 1.9198 -0.60001"
        rpy="0 0 0" />
      <mass
        value="12.276" />
      <inertia
        ixx="0.24694"
        ixy="1.3051E-16"
        ixz="5.9019E-11"
        iyy="0.4497"
        iyz="2.1344E-08"
        izz="0.23048" />
    </inertial>
    <visual>
      <origin
        xyz="0 0 0"
        rpy="0 0 0" />
      <geometry>
        <mesh
          filename="package://mechatronic_wheel_urdf/meshes/Body.STL" />
      </geometry>
      <material
        name="">
        <color
          rgba="0.75294 0.75294 0.75294 1" />
      </material>
    </visual>
    <collision>
      <origin
        xyz="0 0 0"
        rpy="0 0 0" />
      <geometry>
        <mesh
          filename="package://mechatronic_wheel_urdf/meshes/Body.STL" />
      </geometry>
    </collision>
  </link>
  <link
    name="Wheel_Leg_1">
    <inertial>
      <origin
        xyz="-0.084252 0.14235 0.11887"
        rpy="0 0 0" />
      <mass
        value="21.646" />
      <inertia
        ixx="0.09594"
        ixy="0.00049361"
        ixz="-0.002296"
        iyy="0.040872"
        iyz="0.0052055"
        izz="0.071942" />
    </inertial>
    <visual>
      <origin
        xyz="0 0 0"
        rpy="0 0 0" />
      <geometry>
        <mesh
          filename="package://mechatronic_wheel_urdf/meshes/Wheel_Leg_1.STL" />
      </geometry>
      <material
        name="">
        <color
          rgba="0.75294 0.75294 0.75294 1" />
      </material>
    </visual>
    <collision>
      <origin
        xyz="0 0 0"
        rpy="0 0 0" />
      <geometry>
        <mesh
          filename="package://mechatronic_wheel_urdf/meshes/Wheel_Leg_1.STL" />
      </geometry>
    </collision>
  </link>
  <joint
    name="Fixed_Joint_1"
    type="fixed">
    <origin
      xyz="-0.458962061523754 0.672071530720815 1.73207950566572"
      rpy="1.5707963267949 0 3.04706793911628" />
    <parent
      link="Body" />
    <child
      link="Wheel_Leg_1" />
    <axis
      xyz="0 0 0" />
  </joint>
  <link
    name="Wheel_Arm_1">
    <inertial>
      <origin
        xyz="1.0537E-06 2.1145E-07 0.064075"
        rpy="0 0 0" />
      <mass
        value="1.0657" />
      <inertia
        ixx="0.0027869"
        ixy="-3.6154E-09"
        ixz="-2.0135E-11"
        iyy="0.0030328"
        iyz="7.1174E-10"
        izz="0.00038231" />
    </inertial>
    <visual>
      <origin
        xyz="0 0 0"
        rpy="0 0 0" />
      <geometry>
        <mesh
          filename="package://mechatronic_wheel_urdf/meshes/Wheel_Arm_1.STL" />
      </geometry>
      <material
        name="">
        <color
          rgba="0.75294 0.75294 0.75294 1" />
      </material>
    </visual>
    <collision>
      <origin
        xyz="0 0 0"
        rpy="0 0 0" />
      <geometry>
        <mesh
          filename="package://mechatronic_wheel_urdf/meshes/Wheel_Arm_1.STL" />
      </geometry>
    </collision>
  </link>
  <joint
    name="Prismatic_Joint_1"
    type="prismatic">
    <origin
      xyz="-0.0811760992612787 -0.0173248477560364 0.151317807700735"
      rpy="-1.5707963267949 0.094524714473512 0" />
    <parent
      link="Wheel_Leg_1" />
    <child
      link="Wheel_Arm_1" />
    <axis
      xyz="0 0 -1" />
    <limit
      lower="0"
      upper="0.1"
      effort="1500"
      velocity="0.012" />
    <dynamics
      damping="0.1"
      friction="5" />
  </joint>
  <link
    name="Wheel_Steering_1">
    <inertial>
      <origin
        xyz="-0.00264547586329095 0.0696549681507643 -0.0862401478083892"
        rpy="0 0 0" />
      <mass
        value="1.76193110760717" />
      <inertia
        ixx="0.00198196578188312"
        ixy="2.77801323872854E-09"
        ixz="-4.91036823715988E-10"
        iyy="0.001171627765775"
        iyz="-6.91447848235305E-05"
        izz="0.00231982057638236" />
    </inertial>
    <visual>
      <origin
        xyz="0 0 0"
        rpy="0 0 0" />
      <geometry>
        <mesh
          filename="package://mechatronic_wheel_urdf/meshes/Wheel_Steering_1.STL" />
      </geometry>
      <material
        name="">
        <color
          rgba="0.752941176470588 0.752941176470588 0.752941176470588 1" />
      </material>
    </visual>
    <collision>
      <origin
        xyz="0 0 0"
        rpy="0 0 0" />
      <geometry>
        <mesh
          filename="package://mechatronic_wheel_urdf/meshes/Wheel_Steering_1.STL" />
      </geometry>
    </collision>
  </link>
  <joint
    name="Steering_Joint_1"
    type="revolute">
    <origin
      xyz="0 0 0.0139999999999998"
      rpy="0 0 0" />
    <parent
      link="Wheel_Arm_1" />
    <child
      link="Wheel_Steering_1" />
    <axis
      xyz="0 0 -1" />
    <limit
      lower="-1.047"
      upper="1.047"
      effort="25.5"
      velocity="2" />
    <calibration
      rising="0.05"
      falling="0.02" />
    <dynamics
      damping="0.01"
      friction="0.8" />
  </joint>
  <link
    name="Wheel_Rotating_1">
    <inertial>
      <origin
        xyz="-6.70674948466399E-07 5.15937115252996E-08 0.0307772172820633"
        rpy="0 0 0" />
      <mass
        value="2.43383574860161" />
      <inertia
        ixx="0.00377983221037614"
        ixy="6.16165719302865E-08"
        ixz="-2.87930516026538E-08"
        iyy="0.00377991708658644"
        iyz="-3.04086352610987E-08"
        izz="0.00638307835734237" />
    </inertial>
    <visual>
      <origin
        xyz="0 0 0"
        rpy="0 0 0" />
      <geometry>
        <mesh
          filename="package://mechatronic_wheel_urdf/meshes/Wheel_Rotating_1.STL" />
      </geometry>
      <material
        name="">
        <color
          rgba="0.752941176470588 0.752941176470588 0.752941176470588 1" />
      </material>
    </visual>
    <collision>
      <origin
        xyz="0 0 0"
        rpy="0 0 0" />
      <geometry>
        <mesh
          filename="package://mechatronic_wheel_urdf/meshes/Wheel_Rotating_1.STL" />
      </geometry>
    </collision>
  </link>
  <joint
    name="Rotating_Joint_1"
    type="continuous">
    <origin
      xyz="-0.005 -0.03375 -0.13194"
      rpy="1.5708 0 3.1416" />
    <parent
      link="Wheel_Steering_1" />
    <child
      link="Wheel_Rotating_1" />
    <axis
      xyz="0 0 -1" />
    <limit
      lower="0"
      upper="0"
      effort="6"
      velocity="84.1" />
    <calibration
      rising="0.12"
      falling="0.05" />
    <dynamics
      damping="0.01"
      friction="0.8" />
  </joint>
  <link
    name="Wheel_Leg_2">
    <inertial>
      <origin
        xyz="-0.0842515331336085 0.142349951358605 0.118869833879782"
        rpy="0 0 0" />
      <mass
        value="21.6465005280285" />
      <inertia
        ixx="0.095939920806334"
        ixy="0.000493599869216662"
        ixz="-0.00229592135160408"
        iyy="0.0408725009716719"
        iyz="0.00520551514524703"
        izz="0.0719423439584347" />
    </inertial>
    <visual>
      <origin
        xyz="0 0 0"
        rpy="0 0 0" />
      <geometry>
        <mesh
          filename="package://mechatronic_wheel_urdf/meshes/Wheel_Leg_2.STL" />
      </geometry>
      <material
        name="">
        <color
          rgba="0.752941176470588 0.752941176470588 0.752941176470588 1" />
      </material>
    </visual>
    <collision>
      <origin
        xyz="0 0 0"
        rpy="0 0 0" />
      <geometry>
        <mesh
          filename="package://mechatronic_wheel_urdf/meshes/Wheel_Leg_2.STL" />
      </geometry>
    </collision>
  </link>
  <joint
    name="Fixed_Joint_2"
    type="fixed">
    <origin
      xyz="0.121037938476246 0.672071528641097 1.73207950566571"
      rpy="1.5707963267949 0 3.04706793911628" />
    <parent
      link="Body" />
    <child
      link="Wheel_Leg_2" />
    <axis
      xyz="0 0 0" />
  </joint>
  <link
    name="Wheel_Arm_2">
    <inertial>
      <origin
        xyz="1.05371572853286E-06 2.11452870324536E-07 0.0640750160980057"
        rpy="0 0 0" />
      <mass
        value="1.06570722412908" />
      <inertia
        ixx="0.00278693724209937"
        ixy="-3.6154288513778E-09"
        ixz="-2.01353720706103E-11"
        iyy="0.00303280004772249"
        iyz="7.11738987695198E-10"
        izz="0.000382312139775852" />
    </inertial>
    <visual>
      <origin
        xyz="0 0 0"
        rpy="0 0 0" />
      <geometry>
        <mesh
          filename="package://mechatronic_wheel_urdf/meshes/Wheel_Arm_2.STL" />
      </geometry>
      <material
        name="">
        <color
          rgba="0.752941176470588 0.752941176470588 0.752941176470588 1" />
      </material>
    </visual>
    <collision>
      <origin
        xyz="0 0 0"
        rpy="0 0 0" />
      <geometry>
        <mesh
          filename="package://mechatronic_wheel_urdf/meshes/Wheel_Arm_2.STL" />
      </geometry>
    </collision>
  </link>
  <joint
    name="Prismatic_Joint_2"
    type="prismatic">
    <origin
      xyz="-0.081176099261279 -0.0173248477560359 0.151317807700734"
      rpy="-1.5707963267949 0.094524714473512 0" />
    <parent
      link="Wheel_Leg_2" />
    <child
      link="Wheel_Arm_2" />
    <axis
      xyz="0 0 -1" />
    <limit
      lower="0"
      upper="0.1"
      effort="1500"
      velocity="0.012" />
    <dynamics
      damping="0.1"
      friction="5" />
  </joint>
  <link
    name="Wheel_Steering_2">
    <inertial>
      <origin
        xyz="-0.00264547585328498 0.0696549681180505 -0.0862401477625196"
        rpy="0 0 0" />
      <mass
        value="1.76193110843122" />
      <inertia
        ixx="0.00198196578190544"
        ixy="2.77801408979138E-09"
        ixz="-4.91043098378315E-10"
        iyy="0.00117162776579707"
        iyz="-6.91447848224236E-05"
        izz="0.0023198205763831" />
    </inertial>
    <visual>
      <origin
        xyz="0 0 0"
        rpy="0 0 0" />
      <geometry>
        <mesh
          filename="package://mechatronic_wheel_urdf/meshes/Wheel_Steering_2.STL" />
      </geometry>
      <material
        name="">
        <color
          rgba="0.752941176470588 0.752941176470588 0.752941176470588 1" />
      </material>
    </visual>
    <collision>
      <origin
        xyz="0 0 0"
        rpy="0 0 0" />
      <geometry>
        <mesh
          filename="package://mechatronic_wheel_urdf/meshes/Wheel_Steering_2.STL" />
      </geometry>
    </collision>
  </link>
  <joint
    name="Steering_Joint_2"
    type="revolute">
    <origin
      xyz="0 0 0.014"
      rpy="0 0 0" />
    <parent
      link="Wheel_Arm_2" />
    <child
      link="Wheel_Steering_2" />
    <axis
      xyz="0 0 -1" />
    <limit
      lower="-1.047"
      upper="1.047"
      effort="25.5"
      velocity="2" />
    <calibration
      rising="0.05"
      falling="0.02" />
    <dynamics
      damping="0.01"
      friction="0.8" />
  </joint>
  <link
    name="Wheel_Rotating_2">
    <inertial>
      <origin
        xyz="1.91665153276288E-07 -6.55501188218111E-07 0.0294463536332772"
        rpy="0 0 0" />
      <mass
        value="2.43383589638632" />
      <inertia
        ixx="0.00377994752616419"
        ixy="-2.0188075440018E-08"
        ixz="3.86150010804337E-08"
        iyy="0.00377980194106551"
        iyz="-1.66862319297987E-08"
        izz="0.00638307849176644" />
    </inertial>
    <visual>
      <origin
        xyz="0 0 0"
        rpy="0 0 0" />
      <geometry>
        <mesh
          filename="package://mechatronic_wheel_urdf/meshes/Wheel_Rotating_2.STL" />
      </geometry>
      <material
        name="">
        <color
          rgba="0.752941176470588 0.752941176470588 0.752941176470588 1" />
      </material>
    </visual>
    <collision>
      <origin
        xyz="0 0 0"
        rpy="0 0 0" />
      <geometry>
        <mesh
          filename="package://mechatronic_wheel_urdf/meshes/Wheel_Rotating_2.STL" />
      </geometry>
    </collision>
  </link>
  <joint
    name="Rotating_Joint_2"
    type="continuous">
    <origin
      xyz="-0.005 -0.032419 -0.13194"
      rpy="1.5708 0 3.1416" />
    <parent
      link="Wheel_Steering_2" />
    <child
      link="Wheel_Rotating_2" />
    <axis
      xyz="0 0 -1" />
    <limit
      lower="0"
      upper="0"
      effort="6"
      velocity="84.1" />
    <calibration
      rising="0.12"
      falling="0.05" />
    <dynamics
      damping="0.01"
      friction="0.8" />
  </joint>
  <link
    name="Wheel_Leg_3">
    <inertial>
      <origin
        xyz="-0.0846059672214333 0.14234994916718 0.0512470132045877"
        rpy="0 0 0" />
      <mass
        value="21.6464989377523" />
      <inertia
        ixx="0.0959398694986743"
        ixy="0.000493614164014051"
        ixz="-0.00229595522905184"
        iyy="0.0408724695434011"
        iyz="0.00520549117870836"
        izz="0.0719423409059822" />
    </inertial>
    <visual>
      <origin
        xyz="0 0 0"
        rpy="0 0 0" />
      <geometry>
        <mesh
          filename="package://mechatronic_wheel_urdf/meshes/Wheel_Leg_3.STL" />
      </geometry>
      <material
        name="">
        <color
          rgba="0.752941176470588 0.752941176470588 0.752941176470588 1" />
      </material>
    </visual>
    <collision>
      <origin
        xyz="0 0 0"
        rpy="0 0 0" />
      <geometry>
        <mesh
          filename="package://mechatronic_wheel_urdf/meshes/Wheel_Leg_3.STL" />
      </geometry>
    </collision>
  </link>
  <joint
    name="Fixed_Joint_3"
    type="fixed">
    <origin
      xyz="-0.274800316965291 0.460678276574732 1.73207950566572"
      rpy="1.5707963267949 0 -0.0945247144735175" />
    <parent
      link="Body" />
    <child
      link="Wheel_Leg_3" />
    <axis
      xyz="0 0 0" />
  </joint>
  <link
    name="Wheel_Arm_3">
    <inertial>
      <origin
        xyz="-1.05371572944879E-06 -2.11452870380047E-07 0.0640750160980044"
        rpy="0 0 0" />
      <mass
        value="1.06570722412908" />
      <inertia
        ixx="0.0027869372420994"
        ixy="-3.61542885102671E-09"
        ixz="2.0135374003635E-11"
        iyy="0.00303280004772252"
        iyz="-7.11738990196689E-10"
        izz="0.000382312139775854" />
    </inertial>
    <visual>
      <origin
        xyz="0 0 0"
        rpy="0 0 0" />
      <geometry>
        <mesh
          filename="package://mechatronic_wheel_urdf/meshes/Wheel_Arm_3.STL" />
      </geometry>
      <material
        name="">
        <color
          rgba="0.752941176470588 0.752941176470588 0.752941176470588 1" />
      </material>
    </visual>
    <collision>
      <origin
        xyz="0 0 0"
        rpy="0 0 0" />
      <geometry>
        <mesh
          filename="package://mechatronic_wheel_urdf/meshes/Wheel_Arm_3.STL" />
      </geometry>
    </collision>
  </link>
  <joint
    name="Prismatic_Joint_3"
    type="prismatic">
    <origin
      xyz="-0.0815305412407084 -0.0173248477560364 0.0836949744534756"
      rpy="1.5707963267949 -0.0945247144735175 3.14159265358979" />
    <parent
      link="Wheel_Leg_3" />
    <child
      link="Wheel_Arm_3" />
    <axis
      xyz="0 0 -1" />
    <limit
      lower="0"
      upper="0.1"
      effort="1500"
      velocity="0.012" />
    <dynamics
      damping="0.1"
      friction="5" />
  </joint>
  <link
    name="Wheel_Steering_3">
    <inertial>
      <origin
        xyz="0.00264547584907721 -0.0696549681284998 -0.0862401477768258"
        rpy="0 0 0" />
      <mass
        value="1.76193110816447" />
      <inertia
        ixx="0.00198196578189706"
        ixy="2.7780141123649E-09"
        ixz="4.91041068100783E-10"
        iyy="0.00117162776578546"
        iyz="6.91447848214601E-05"
        izz="0.00231982057637865" />
    </inertial>
    <visual>
      <origin
        xyz="0 0 0"
        rpy="0 0 0" />
      <geometry>
        <mesh
          filename="package://mechatronic_wheel_urdf/meshes/Wheel_Steering_3.STL" />
      </geometry>
      <material
        name="">
        <color
          rgba="0.752941176470588 0.752941176470588 0.752941176470588 1" />
      </material>
    </visual>
    <collision>
      <origin
        xyz="0 0 0"
        rpy="0 0 0" />
      <geometry>
        <mesh
          filename="package://mechatronic_wheel_urdf/meshes/Wheel_Steering_3.STL" />
      </geometry>
    </collision>
  </link>
  <joint
    name="Steering_Joint_3"
    type="revolute">
    <origin
      xyz="0 0 0.014"
      rpy="0 0 0" />
    <parent
      link="Wheel_Arm_3" />
    <child
      link="Wheel_Steering_3" />
    <axis
      xyz="0 0 -1" />
    <limit
      lower="-1.047"
      upper="1.047"
      effort="25.5"
      velocity="2" />
    <calibration
      rising="0.05"
      falling="0.02" />
    <dynamics
      damping="0.01"
      friction="0.8" />
  </joint>
  <link
    name="Wheel_Rotating_3">
    <inertial>
      <origin
        xyz="6.7913190066049E-07 2.73945768292094E-08 -0.0307772193197284"
        rpy="0 0 0" />
      <mass
        value="2.43383536203651" />
      <inertia
        ixx="0.0037798320729838"
        ixy="-6.15505065954813E-08"
        ixz="-2.8884300726216E-08"
        iyy="0.00377991657144083"
        iyz="3.10354312673607E-08"
        izz="0.00638307785089282" />
    </inertial>
    <visual>
      <origin
        xyz="0 0 0"
        rpy="0 0 0" />
      <geometry>
        <mesh
          filename="package://mechatronic_wheel_urdf/meshes/Wheel_Rotating_3.STL" />
      </geometry>
      <material
        name="">
        <color
          rgba="0.752941176470588 0.752941176470588 0.752941176470588 1" />
      </material>
    </visual>
    <collision>
      <origin
        xyz="0 0 0"
        rpy="0 0 0" />
      <geometry>
        <mesh
          filename="package://mechatronic_wheel_urdf/meshes/Wheel_Rotating_3.STL" />
      </geometry>
    </collision>
  </link>
  <joint
    name="Rotating_Joint_3"
    type="continuous">
    <origin
      xyz="0.005 0.03375 -0.13194"
      rpy="1.5708 0 3.1416" />
    <parent
      link="Wheel_Steering_3" />
    <child
      link="Wheel_Rotating_3" />
    <axis
      xyz="0 0 1" />
    <limit
      lower="0"
      upper="0"
      effort="6"
      velocity="84.1" />
    <calibration
      rising="0.12"
      falling="0.05" />
    <dynamics
      damping="0.01"
      friction="0.8" />
  </joint>
  <link
    name="Wheel_Leg_4">
    <inertial>
      <origin
        xyz="-0.0846059672222562 0.142349949167195 0.0512470132044782"
        rpy="0 0 0" />
      <mass
        value="21.6464989382765" />
      <inertia
        ixx="0.0959398694984719"
        ixy="0.000493614163906364"
        ixz="-0.0022959552290621"
        iyy="0.0408724695431965"
        iyz="0.00520549117877708"
        izz="0.0719423409062316" />
    </inertial>
    <visual>
      <origin
        xyz="0 0 0"
        rpy="0 0 0" />
      <geometry>
        <mesh
          filename="package://mechatronic_wheel_urdf/meshes/Wheel_Leg_4.STL" />
      </geometry>
      <material
        name="">
        <color
          rgba="0.752941176470588 0.752941176470588 0.752941176470588 1" />
      </material>
    </visual>
    <collision>
      <origin
        xyz="0 0 0"
        rpy="0 0 0" />
      <geometry>
        <mesh
          filename="package://mechatronic_wheel_urdf/meshes/Wheel_Leg_4.STL" />
      </geometry>
    </collision>
  </link>
  <joint
    name="Fixed_Joint_4"
    type="fixed">
    <origin
      xyz="0.3052 0.46068 1.7321"
      rpy="1.5708 0 -0.094525" />
    <parent
      link="Body" />
    <child
      link="Wheel_Leg_4" />
    <axis
      xyz="0 0 0" />
  </joint>
  <link
    name="Wheel_Arm_4">
    <inertial>
      <origin
        xyz="-1.0537157297541E-06 -2.11452870269024E-07 0.0640750160980048"
        rpy="0 0 0" />
      <mass
        value="1.06570722412909" />
      <inertia
        ixx="0.0027869372420994"
        ixy="-3.61542885166407E-09"
        ixz="2.01353730635597E-11"
        iyy="0.00303280004772252"
        iyz="-7.11738983209435E-10"
        izz="0.000382312139775855" />
    </inertial>
    <visual>
      <origin
        xyz="0 0 0"
        rpy="0 0 0" />
      <geometry>
        <mesh
          filename="package://mechatronic_wheel_urdf/meshes/Wheel_Arm_4.STL" />
      </geometry>
      <material
        name="">
        <color
          rgba="0.752941176470588 0.752941176470588 0.752941176470588 1" />
      </material>
    </visual>
    <collision>
      <origin
        xyz="0 0 0"
        rpy="0 0 0" />
      <geometry>
        <mesh
          filename="package://mechatronic_wheel_urdf/meshes/Wheel_Arm_4.STL" />
      </geometry>
    </collision>
  </link>
  <joint
    name="Prismatic_Joint_4"
    type="prismatic">
    <origin
      xyz="-0.081531 -0.017325 0.083695"
      rpy="1.5708 -0.094525 3.1416" />
    <parent
      link="Wheel_Leg_4" />
    <child
      link="Wheel_Arm_4" />
    <axis
      xyz="0 0 -1" />
    <limit
      lower="0"
      upper="0.1"
      effort="1500"
      velocity="0.012" />
    <dynamics
      damping="0.1"
      friction="5" />
  </joint>
  <link
    name="Wheel_Steering_4">
    <inertial>
      <origin
        xyz="0.002354523895963 0.0456976707942123 -0.10207410517055"
        rpy="0 0 0" />
      <mass
        value="1.76193110816667" />
      <inertia
        ixx="0.00198196578190133"
        ixy="-4.9079151255396E-10"
        ixz="-2.78091920259994E-09"
        iyy="0.00231982057637827"
        iyz="6.9144784823207E-05"
        izz="0.00117162776578764" />
    </inertial>
    <visual>
      <origin
        xyz="0 0 0"
        rpy="0 0 0" />
      <geometry>
        <mesh
          filename="package://mechatronic_wheel_urdf/meshes/Wheel_Steering_4.STL" />
      </geometry>
      <material
        name="">
        <color
          rgba="0.752941176470588 0.752941176470588 0.752941176470588 1" />
      </material>
    </visual>
    <collision>
      <origin
        xyz="0 0 0"
        rpy="0 0 0" />
      <geometry>
        <mesh
          filename="package://mechatronic_wheel_urdf/meshes/Wheel_Steering_4.STL" />
      </geometry>
    </collision>
  </link>
  <joint
    name="Steering_Joint_4"
    type="revolute">
    <origin
      xyz="0.005 0.032419 -0.11794"
      rpy="1.5708 0 3.1416" />
    <parent
      link="Wheel_Arm_4" />
    <child
      link="Wheel_Steering_4" />
    <axis
      xyz="0 -1 0" />
    <limit
      lower="-1.047"
      upper="1.047"
      effort="25.5"
      velocity="2" />
    <calibration
      rising="0.05"
      falling="0.02" />
    <dynamics
      damping="0.01"
      friction="0.8" />
  </joint>
  <link
    name="Wheel_Rotating_4">
    <inertial>
      <origin
        xyz="6.81058461071693E-07 4.71989358707958E-08 -0.0294463611050717"
        rpy="0 0 0" />
      <mass
        value="2.43383448107493" />
      <inertia
        ixx="0.00377983171291225"
        ixy="-6.23437055287201E-08"
        ixz="-2.89084009946914E-08"
        iyy="0.00377991554427767"
        iyz="3.04262020965937E-08"
        izz="0.00638307677323809" />
    </inertial>
    <visual>
      <origin
        xyz="0 0 0"
        rpy="0 0 0" />
      <geometry>
        <mesh
          filename="package://mechatronic_wheel_urdf/meshes/Wheel_Rotating_4.STL" />
      </geometry>
      <material
        name="">
        <color
          rgba="0.752941176470588 0.752941176470588 0.752941176470588 1" />
      </material>
    </visual>
    <collision>
      <origin
        xyz="0 0 0"
        rpy="0 0 0" />
      <geometry>
        <mesh
          filename="package://mechatronic_wheel_urdf/meshes/Wheel_Rotating_4.STL" />
      </geometry>
    </collision>
  </link>
  <joint
    name="Rotating_Joint_4"
    type="continuous">
    <origin
      xyz="0 0 0"
      rpy="0 0 0" />
    <parent
      link="Wheel_Steering_4" />
    <child
      link="Wheel_Rotating_4" />
    <axis
      xyz="0 0 1" />
    <limit
      lower="0"
      upper="0"
      effort="6"
      velocity="84.1" />
    <calibration
      rising="0.12"
      falling="0.05" />
    <dynamics
      damping="0.01"
      friction="0.8" />
  </joint>
</robot>